Workbook
Name _Hlk2685582: '346_Inv053_A'!#REF!
Name _Hlk2685582: '420_Inv055_A'!#REF!
Name _Hlk2685582: '421_Inv056_A'!#REF!
Name _Hlk2685582: '73_Inv019_A'!$D$48
Name _Hlk2685582: '74_Inv020_A'!#REF!
Name _Hlk2685582: '75_Inv021_A'!#REF!
Name _Hlk2685582: '76_Inv022_A'!#REF!
Name _Hlk2685582: '77_Inv023_A'!#REF!
Name _Hlk2685582: '78_Inv024_A'!#REF!
Name _Hlk2685582: '79_Inv025_A'!#REF!
Name _Hlk2685582: '80_Inv026_A'!#REF!
Name _Hlk2685582: '81_Inv027_A'!#REF!
Name _Hlk2685582: '82_Inv028_A'!#REF!
Name _Hlk2685582: '83_Inv029_A'!#REF!
Name _Hlk2685582: '84_Inv030_A'!#REF!
Name _Hlk2685582: '85_Inv031_A'!#REF!
Name _Hlk2685582: '86_Inv032_A'!#REF!
Name _Hlk2685582: '87_Inv033_A'!#REF!
Name _Hlk2685582: '88_Inv034_A'!#REF!
Name _Hlk2685582: '89_Inv035_A'!#REF!
Name _Hlk2685582: '90_Inv036_A'!#REF!
Name _Hlk50047068: '273_LoginValidate'!$D$27
Name _Hlk50047068: '274_QueryLoginResult'!#REF!
Name _Hlk530658180: '102_Inv048_A'!#REF!
Name _Hlk530658180: '343_Inv050_A'!$D$50
Name _Hlk530658180: '344_Inv051_A'!$D$48
Name _Hlk530658180: '345_Inv052_A'!$D$50
Name _Hlk530658180: '346_Inv053_A'!#REF!
Name _Hlk530658180: '419_Inv054_A'!#REF!
Name _Hlk530658180: '420_Inv055_A'!#REF!
Name _Hlk530658180: '421_Inv056_A'!#REF!
Name _Hlk530658180: '55_Inv001_A'!#REF!
Name _Hlk530658180: '56_Inv002_A'!#REF!
Name _Hlk530658180: '57_Inv003_A'!$D$43
Name _Hlk530658180: '58_Inv004_A'!$D$46
Name _Hlk530658180: '59_Inv005_A'!$D$52
Name _Hlk530658180: '60_Inv006_A'!#REF!
Name _Hlk530658180: '61_Inv007_A'!#REF!
Name _Hlk530658180: '62_Inv008_A'!#REF!
Name _Hlk530658180: '63_Inv009_A'!#REF!
Name _Hlk530658180: '64_Inv010_A'!#REF!
Name _Hlk530658180: '65_Inv011_A'!#REF!
Name _Hlk530658180: '66_Inv012_A'!$D$43
Name _Hlk530658180: '67_Inv013_A'!$D$47
Name _Hlk530658180: '68_Inv014_A'!$D$48
Name _Hlk530658180: '69_Inv015_A'!$D$41
Name _Hlk530658180: '70_Inv016_A'!$D$44
Name _Hlk530658180: '71_Inv017_A'!$D$44
Name _Hlk530658180: '72_Inv018_A'!$D$36
Name _Hlk530658180: '73_Inv019_A'!$D$64
Name _Hlk530658180: '74_Inv020_A'!$D$37
Name _Hlk530658180: '75_Inv021_A'!#REF!
Name _Hlk530658180: '76_Inv022_A'!#REF!
Name _Hlk530658180: '77_Inv023_A'!#REF!
Name _Hlk530658180: '78_Inv024_A'!#REF!
Name _Hlk530658180: '79_Inv025_A'!#REF!
Name _Hlk530658180: '80_Inv026_A'!#REF!
Name _Hlk530658180: '81_Inv027_A'!#REF!
Name _Hlk530658180: '82_Inv028_A'!#REF!
Name _Hlk530658180: '83_Inv029_A'!#REF!

Sheet 結果
B1: 表名 | C1: K5值 | D1: L5值 | E1: M5值 | F1: K6值 | G1: L6值 | H1: M6值 | I1: K6文字 | J1: L6文字 | K1: M6文字
A2: 001 | B2: 1_RequestSpot | C2: SIT API URL | D2: UAT API URL | E2: PROD API URL | F2: http://10.11.22.126:886/ETSRateService.asm/RequestSpot | G2: http://10.11.66.160:886/ETSRateService.asm/RequestSpot | H2: http://10.16.1.11:886/ETSRateService.asm/RequestSpot | I2: =IF(ISERROR(F2), "缺SIT API URL", IF(F2=0, "缺SIT API URL", "")) | J2: =IF(ISERROR(G2), "缺UAT API URL", IF(G2=0, "缺UAT API URL", "")) | K2: =IF(ISERROR(H2), "缺PROD API URL", IF(H2=0, "缺PROD API URL", ""))
A3: 002 | B3: 2_RequestSpot2 | C3: SIT API URL | D3: UAT API URL | E3: PROD API URL | F3: http://10.11.22.126:886/ETSRateService.asm/RequestSpot2 | G3: http://10.11.66.160:886/ETSRateService.asm/RequestSpot2 | H3: http://10.16.1.11:886/ETSRateService.asm/RequestSpot2 | I3: =IF(ISERROR(F3), "缺SIT API URL", IF(F3=0, "缺SIT API URL", "")) | J3: =IF(ISERROR(G3), "缺UAT API URL", IF(G3=0, "缺UAT API URL", "")) | K3: =IF(ISERROR(H3), "缺PROD API URL", IF(H3=0, "缺PROD API URL", ""))
A4: 003 | B4: 3_InsertSpotDeal | C4: SIT API URL | D4: UAT API URL | E4: PROD API URL | F4: http://10.11.22.126:886/ETSRateService.asm/InsertSpotDeal | G4: http://10.11.66.160:886/ETSRateService.asm/InsertSpotDeal | H4: http://10.16.1.11:886/ETSRateService.asm/InsertSpotDeal | I4: =IF(ISERROR(F4), "缺SIT API URL", IF(F4=0, "缺SIT API URL", "")) | J4: =IF(ISERROR(G4), "缺UAT API URL", IF(G4=0, "缺UAT API URL", "")) | K4: =IF(ISERROR(H4), "缺PROD API URL", IF(H4=0, "缺PROD API URL", ""))
A5: 004 | B5: 4_GetReferRate | C5: SIT API URL | D5: UAT API URL | E5: PROD API URL | F5: http://10.11.22.126:886/ETSRateService.asm/GetReferRate | G5: http://10.11.66.160:886/ETSRateService.asm/GetReferRate | H5: http://10.16.1.11:886/ETSRateService.asm/GetReferRate | I5: =IF(ISERROR(F5), "缺SIT API URL", IF(F5=0, "缺SIT API URL", "")) | J5: =IF(ISERROR(G5), "缺UAT API URL", IF(G5=0, "缺UAT API URL", "")) | K5: =IF(ISERROR(H5), "缺PROD API URL", IF(H5=0, "缺PROD API URL", ""))
A6: 005 | B6: 5_FUNINSERTFXORDER | C6: SIT API URL | D6: UAT API URL | E6: PROD API URL | F6: http://10.11.35.51:8091/FxOrderWebService.asmx/funFxOrderWS | G6: http://10.11.66.136:8091/FxOrderWebService.asmx/funFxOrderWS | H6: http://10.16.1.29:8091/FxOrderWebService.asmx/funFxOrderWS | I6: =IF(ISERROR(F6), "缺SIT API URL", IF(F6=0, "缺SIT API URL", "")) | J6: =IF(ISERROR(G6), "缺UAT API URL", IF(G6=0, "缺UAT API URL", "")) | K6: =IF(ISERROR(H6), "缺PROD API URL", IF(H6=0, "缺PROD API URL", ""))
A7: 006 | B7: 6_FUNDELETEFXORDER | C7: SIT API URL | D7: UAT API URL | E7: PROD API URL | F7: http://10.11.35.51:8091/FxOrderWebService.asmx/funFxOrderWS | G7: http://10.11.66.136:8091/FxOrderWebService.asmx/funFxOrderWS | H7: http://10.16.1.29:8091/FxOrderWebService.asmx/funFxOrderWS | I7: =IF(ISERROR(F7), "缺SIT API URL", IF(F7=0, "缺SIT API URL", "")) | J7: =IF(ISERROR(G7), "缺UAT API URL", IF(G7=0, "缺UAT API URL", "")) | K7: =IF(ISERROR(H7), "缺PROD API URL", IF(H7=0, "缺PROD API URL", ""))
A8: 007 | B8: 7_MemberRegisterCheck | C8: SIT API URL | D8: UAT API URL | E8: PROD API URL | F8: http://sinopac.eweb.backend/api/Member/MemberRegisterCheck | H8: http://sinopac.eweb.backend/api/Member/MemberRegisterCheck | I8: =IF(ISERROR(F8), "缺SIT API URL", IF(F8=0, "缺SIT API URL", "")) | J8: =IF(ISERROR(G8), "缺UAT API URL", IF(G8=0, "缺UAT API URL", "")) -> 缺UAT API URL | K8: =IF(ISERROR(H8), "缺PROD API URL", IF(H8=0, "缺PROD API URL", ""))
A9: 008 | B9: 8_LatestTx | C9: SIT API URL | D9: UAT API URL | E9: PROD API URL | F9: http://sinopac.eweb.backend/api/Accounting/LatestTx | H9: http://sinopac.eweb.backend/api/Accounting/LatestTx | I9: =IF(ISERROR(F9), "缺SIT API URL", IF(F9=0, "缺SIT API URL", "")) | J9: =IF(ISERROR(G9), "缺UAT API URL", IF(G9=0, "缺UAT API URL", "")) -> 缺UAT API URL | K9: =IF(ISERROR(H9), "缺PROD API URL", IF(H9=0, "缺PROD API URL", ""))
A10: 009 | B10: 9_OutstandingDetail | C10: SIT API URL | D10: UAT API URL | E10: PROD API URL | F10: http://sinopac.eweb.backend/api/Accounting/OutstandingDetail | H10: http://sinopac.eweb.backend/api/Accounting/OutstandingDetail | I10: =IF(ISERROR(F10), "缺SIT API URL", IF(F10=0, "缺SIT API URL", "")) | J10: =IF(ISERROR(G10), "缺UAT API URL", IF(G10=0, "缺UAT API URL", "")) -> 缺UAT API URL | K10: =IF(ISERROR(H10), "缺PROD API URL", IF(H10=0, "缺PROD API URL", ""))
A11: 010 | B11: 10_RecentBill | C11: SIT API URL | D11: UAT API URL | E11: PROD API URL | F11: http://sinopac.eweb.backend/api/Accounting/RecentBill | H11: http://sinopac.eweb.backend/api/Accounting/RecentBill | I11: =IF(ISERROR(F11), "缺SIT API URL", IF(F11=0, "缺SIT API URL", "")) | J11: =IF(ISERROR(G11), "缺UAT API URL", IF(G11=0, "缺UAT API URL", "")) -> 缺UAT API URL | K11: =IF(ISERROR(H11), "缺PROD API URL", IF(H11=0, "缺PROD API URL", ""))
A12: 011 | B12: 11_OtpState | C12: SIT API URL | D12: UAT API URL | E12: PROD API URL | F12: http://10.11.37.109/OTP/Service/OtpSvc.asmx?op=OtpState | H12: http://10.16.1.28/OTP/Service/OtpSvc.asmx?op=OtpState | I12: =IF(ISERROR(F12), "缺SIT API URL", IF(F12=0, "缺SIT API URL", "")) | J12: =IF(ISERROR(G12), "缺UAT API URL", IF(G12=0, "缺UAT API URL", "")) -> 缺UAT API URL | K12: =IF(ISERROR(H12), "缺PROD API URL", IF(H12=0, "缺PROD API URL", ""))
A13: 012 | B13: 12_cardGetMain | C13: SIT API URL | D13: UAT API URL | E13: PROD API URL | F13: http://10.11.37.109/CARDWebService/MMAQueryMain/QueryMain.asmx?op=cardGetMain | H13: http://172.31.213.9/CARDWebService/MMAQueryMain/QueryMain.asmx?op=cardGetMain | I13: =IF(ISERROR(F13), "缺SIT API URL", IF(F13=0, "缺SIT API URL", "")) | J13: =IF(ISERROR(G13), "缺UAT API URL", IF(G13=0, "缺UAT API URL", "")) -> 缺UAT API URL | K13: =IF(ISERROR(H13), "缺PROD API URL", IF(H13=0, "缺PROD API URL", ""))
A14: 013 | B14: 13_getDAWHORet | C14: SIT API URL | D14: UAT API URL | E14: PROD API URL | F14: http://10.11.37.109/CARDWebService/MMAQueryMain/QueryMain.asmx?op=getDAWHORet | H14: http://172.31.213.9/CARDWebService/MMAQueryMain/QueryMain.asmx?op=getDAWHORet | I14: =IF(ISERROR(F14), "缺SIT API URL", IF(F14=0, "缺SIT API URL", "")) | J14: =IF(ISERROR(G14), "缺UAT API URL", IF(G14=0, "缺UAT API URL", "")) -> 缺UAT API URL | K14: =IF(ISERROR(H14), "缺PROD API URL", IF(H14=0, "缺PROD API URL", ""))
A15: 014 | B15: 14_getDAWHOCardStatus | C15: SIT API URL | D15: UAT API URL | E15: PROD API URL | F15: http://10.11.37.109/CARDWebService/MMAQueryMain/QueryMain.asmx?op=getDAWHOCardStatus | H15: http://172.31.213.9/CARDWebService/MMAQueryMain/QueryMain.asmx?op=getDAWHOCardStatus | I15: =IF(ISERROR(F15), "缺SIT API URL", IF(F15=0, "缺SIT API URL", "")) | J15: =IF(ISERROR(G15), "缺UAT API URL", IF(G15=0, "缺UAT API URL", "")) -> 缺UAT API URL | K15: =IF(ISERROR(H15), "缺PROD API URL", IF(H15=0, "缺PROD API URL", ""))
A16: 015 | B16: 15_getDDFlag | C16: SIT API URL | D16: UAT API URL | E16: PROD API URL | F16: http://10.11.37.109/CARDWebService/MMAQueryMain/QueryMain.asmx?op=getDDFlag | H16: http://172.31.213.9/CARDWebService/MMAQueryMain/QueryMain.asmx?op=getDDFlag | I16: =IF(ISERROR(F16), "缺SIT API URL", IF(F16=0, "缺SIT API URL", "")) | J16: =IF(ISERROR(G16), "缺UAT API URL", IF(G16=0, "缺UAT API URL", "")) -> 缺UAT API URL | K16: =IF(ISERROR(H16), "缺PROD API URL", IF(H16=0, "缺PROD API URL", ""))
A17: 016 | B17: 16_getBLHSHWithPaysum | C17: SIT API URL | D17: UAT API URL | E17: PROD API URL | F17: http://10.11.37.109/CARDWebService/MMAQueryMain/QueryMain.asmx?op=getBLHSHWithPaysum | H17: http://172.31.213.9/CARDWebService/MMAQueryMain/QueryMain.asmx?op=getBLHSHWithPaysum | I17: =IF(ISERROR(F17), "缺SIT API URL", IF(F17=0, "缺SIT API URL", "")) | J17: =IF(ISERROR(G17), "缺UAT API URL", IF(G17=0, "缺UAT API URL", "")) -> 缺UAT API URL | K17: =IF(ISERROR(H17), "缺PROD API URL", IF(H17=0, "缺PROD API URL", ""))
A18: 017 | B18: 17_getMainDcur | C18: SIT API URL | D18: UAT API URL | E18: PROD API URL | F18: http://10.11.37.109/CARDWebService/MMAQueryMain/QueryMain.asmx?op=getMainDcur | H18: http://172.31.213.9/CARDWebService/MMAQueryMain/QueryMain.asmx?op=getMainDcur | I18: =IF(ISERROR(F18), "缺SIT API URL", IF(F18=0, "缺SIT API URL", "")) | J18: =IF(ISERROR(G18), "缺UAT API URL", IF(G18=0, "缺UAT API URL", "")) -> 缺UAT API URL | K18: =IF(ISERROR(H18), "缺PROD API URL", IF(H18=0, "缺PROD API URL", ""))
A19: 018 | B19: 18_Inv01_E | C19: SIT API URL | D19: UAT API URL | E19: PROD API URL | F19: https://10.11.37.36:8080/etfAPIM/ | G19: https://10.11.66.149:8080/etfAPIM/ | H19: https://10.16.1.61:8080/etfAPIM/ | I19: =IF(ISERROR(F19), "缺SIT API URL", IF(F19=0, "缺SIT API URL", "")) | J19: =IF(ISERROR(G19), "缺UAT API URL", IF(G19=0, "缺UAT API URL", "")) | K19: =IF(ISERROR(H19), "缺PROD API URL", IF(H19=0, "缺PROD API URL", ""))
A20: 019 | B20: 19_Inv02_E | C20: SIT API URL | D20: UAT API URL | E20: PROD API URL | F20: https://10.11.37.36:8080/etfAPIM/ | G20: https://10.11.66.149:8080/etfAPIM/ | H20: https://10.16.1.61:8080/etfAPIM/ | I20: =IF(ISERROR(F20), "缺SIT API URL", IF(F20=0, "缺SIT API URL", "")) | J20: =IF(ISERROR(G20), "缺UAT API URL", IF(G20=0, "缺UAT API URL", "")) | K20: =IF(ISERROR(H20), "缺PROD API URL", IF(H20=0, "缺PROD API URL", ""))
A21: 020 | B21: 20_Inv03_E | C21: SIT API URL | D21: UAT API URL | E21: PROD API URL | F21: https://10.11.37.36:8080/etfAPIM/ | G21: https://10.11.66.149:8080/etfAPIM/ | H21: https://10.16.1.61:8080/etfAPIM/ | I21: =IF(ISERROR(F21), "缺SIT API URL", IF(F21=0, "缺SIT API URL", "")) | J21: =IF(ISERROR(G21), "缺UAT API URL", IF(G21=0, "缺UAT API URL", "")) | K21: =IF(ISERROR(H21), "缺PROD API URL", IF(H21=0, "缺PROD API URL", ""))
A22: 021 | B22: 21_Inv04_E | C22: SIT API URL | D22: UAT API URL | E22: PROD API URL | F22: https://10.11.37.36:8080/etfAPIM/ | G22: https://10.11.66.149:8080/etfAPIM/ | H22: https://10.16.1.61:8080/etfAPIM/ | I22: =IF(ISERROR(F22), "缺SIT API URL", IF(F22=0, "缺SIT API URL", "")) | J22: =IF(ISERROR(G22), "缺UAT API URL", IF(G22=0, "缺UAT API URL", "")) | K22: =IF(ISERROR(H22), "缺PROD API URL", IF(H22=0, "缺PROD API URL", ""))
A23: 022 | B23: 22_Inv05_E | C23: SIT API URL | D23: UAT API URL | E23: PROD API URL | F23: https://10.11.37.36:8080/etfAPIM/ | G23: https://10.11.66.149:8080/etfAPIM/ | H23: https://10.16.1.61:8080/etfAPIM/ | I23: =IF(ISERROR(F23), "缺SIT API URL", IF(F23=0, "缺SIT API URL", "")) | J23: =IF(ISERROR(G23), "缺UAT API URL", IF(G23=0, "缺UAT API URL", "")) | K23: =IF(ISERROR(H23), "缺PROD API URL", IF(H23=0, "缺PROD API URL", ""))
A24: 023 | B24: 23_Inv06_E | C24: SIT API URL | D24: UAT API URL | E24: PROD API URL | F24: https://10.11.37.36:8080/etfAPIM/ | G24: https://10.11.66.149:8080/etfAPIM/ | H24: https://10.16.1.61:8080/etfAPIM/ | I24: =IF(ISERROR(F24), "缺SIT API URL", IF(F24=0, "缺SIT API URL", "")) | J24: =IF(ISERROR(G24), "缺UAT API URL", IF(G24=0, "缺UAT API URL", "")) | K24: =IF(ISERROR(H24), "缺PROD API URL", IF(H24=0, "缺PROD API URL", ""))
A25: 024 | B25: 24_Inv07_E | C25: SIT API URL | D25: UAT API URL | E25: PROD API URL | F25: https://10.11.37.36:8080/etfAPIM/ | G25: https://10.11.66.149:8080/etfAPIM/ | H25: https://10.16.1.61:8080/etfAPIM/ | I25: =IF(ISERROR(F25), "缺SIT API URL", IF(F25=0, "缺SIT API URL", "")) | J25: =IF(ISERROR(G25), "缺UAT API URL", IF(G25=0, "缺UAT API URL", "")) | K25: =IF(ISERROR(H25), "缺PROD API URL", IF(H25=0, "缺PROD API URL", ""))
A26: 025 | B26: 25_Inv08_E | C26: SIT API URL | D26: UAT API URL | E26: PROD API URL | F26: https://10.11.37.36:8080/etfAPIM/ | G26: https://10.11.66.149:8080/etfAPIM/ | H26: https://10.16.1.61:8080/etfAPIM/ | I26: =IF(ISERROR(F26), "缺SIT API URL", IF(F26=0, "缺SIT API URL", "")) | J26: =IF(ISERROR(G26), "缺UAT API URL", IF(G26=0, "缺UAT API URL", "")) | K26: =IF(ISERROR(H26), "缺PROD API URL", IF(H26=0, "缺PROD API URL", ""))
A27: 026 | B27: 26_Inv09_E | C27: SIT API URL | D27: UAT API URL | E27: PROD API URL | F27: https://10.11.37.36:8080/etfAPIM/ | G27: https://10.11.66.149:8080/etfAPIM/ | H27: https://10.16.1.61:8080/etfAPIM/ | I27: =IF(ISERROR(F27), "缺SIT API URL", IF(F27=0, "缺SIT API URL", "")) | J27: =IF(ISERROR(G27), "缺UAT API URL", IF(G27=0, "缺UAT API URL", "")) | K27: =IF(ISERROR(H27), "缺PROD API URL", IF(H27=0, "缺PROD API URL", ""))
A28: 027 | B28: 27_Inv10_E | C28: SIT API URL | D28: UAT API URL | E28: PROD API URL | F28: https://10.11.37.36:8080/etfAPIM/ | G28: https://10.11.66.149:8080/etfAPIM/ | H28: https://10.16.1.61:8080/etfAPIM/ | I28: =IF(ISERROR(F28), "缺SIT API URL", IF(F28=0, "缺SIT API URL", "")) | J28: =IF(ISERROR(G28), "缺UAT API URL", IF(G28=0, "缺UAT API URL", "")) | K28: =IF(ISERROR(H28), "缺PROD API URL", IF(H28=0, "缺PROD API URL", ""))
A29: 028 | B29: 28_Inv11_E | C29: SIT API URL | D29: UAT API URL | E29: PROD API URL | F29: https://10.11.37.36:8080/etfAPIM/ | G29: https://10.11.66.149:8080/etfAPIM/ | H29: https://10.16.1.61:8080/etfAPIM/ | I29: =IF(ISERROR(F29), "缺SIT API URL", IF(F29=0, "缺SIT API URL", "")) | J29: =IF(ISERROR(G29), "缺UAT API URL", IF(G29=0, "缺UAT API URL", "")) | K29: =IF(ISERROR(H29), "缺PROD API URL", IF(H29=0, "缺PROD API URL", ""))
A30: 029 | B30: 29_Inv12_E | C30: SIT API URL | D30: UAT API URL | E30: PROD API URL | F30: https://10.11.37.36:8080/etfAPIM/ | G30: https://10.11.66.149:8080/etfAPIM/ | H30: https://10.16.1.61:8080/etfAPIM/ | I30: =IF(ISERROR(F30), "缺SIT API URL", IF(F30=0, "缺SIT API URL", "")) | J30: =IF(ISERROR(G30), "缺UAT API URL", IF(G30=0, "缺UAT API URL", "")) | K30: =IF(ISERROR(H30), "缺PROD API URL", IF(H30=0, "缺PROD API URL", ""))
... A251: 253 | B251: 253_C002 | C251: SIT API URL | D251: UAT API URL | E251: PROD API URL | F251: http://10.11.35.133/pb/Service/ApproveService.asmx?op=eBill_Webservice_yfp | G251: http://10.11.152.102/pb/Service/ApproveService.asmx?op=eBill_Webservice_yfp | H251: http://10.16.1.10/pb/Service/ApproveService.asmx?op=eBill_Webservice_yfp | I251: =IF(ISERROR(F251), "缺SIT API URL", IF(F251=0, "缺SIT API URL", "")) | J251: =IF(ISERROR(G251), "缺UAT API URL", IF(G251=0, "缺UAT API URL", "")) | K251: =IF(ISERROR(H251), "缺PROD API URL", IF(H251=0, "缺PROD API URL", ""))
A252: 254 | B252: 254_C003 | C252: SIT API URL | D252: UAT API URL | E252: PROD API URL | G252: http://10.11.148.3/eBill_Webservice/service1.asmx?op=eBill_Webservice | H252: http://10.12.1.45/eBill_Webservice/service1.asmx?op=eBill_Webservice | I252: =IF(ISERROR(F252), "缺SIT API URL", IF(F252=0, "缺SIT API URL", "")) -> 缺SIT API URL | J252: =IF(ISERROR(G252), "缺UAT API URL", IF(G252=0, "缺UAT API URL", "")) | K252: =IF(ISERROR(H252), "缺PROD API URL", IF(H252=0, "缺PROD API URL", ""))
A253: 255 | B253: 255_C004 | C253: SIT API URL | D253: UAT API URL | E253: PROD API URL | G253: https://videocenter-uat.sinopac.com:8080/VCS/restful/generateApiToken | H253: https://videocenter.sinopac.com:8080/VCS/restful/generateApiToken | I253: =IF(ISERROR(F253), "缺SIT API URL", IF(F253=0, "缺SIT API URL", "")) -> 缺SIT API URL | J253: =IF(ISERROR(G253), "缺UAT API URL", IF(G253=0, "缺UAT API URL", "")) | K253: =IF(ISERROR(H253), "缺PROD API URL", IF(H253=0, "缺PROD API URL", ""))
A254: 256 | B254: 256_C005 | C254: SIT API URL | D254: UAT API URL | E254: PROD API URL | G254: https://videocenter-uat.sinopac.com:8080/VCS/restful/promptCallIn | H254: https://videocenter.sinopac.com:8080/VCS/restful/promptCallIn | I254: =IF(ISERROR(F254), "缺SIT API URL", IF(F254=0, "缺SIT API URL", "")) -> 缺SIT API URL | J254: =IF(ISERROR(G254), "缺UAT API URL", IF(G254=0, "缺UAT API URL", "")) | K254: =IF(ISERROR(H254), "缺PROD API URL", IF(H254=0, "缺PROD API URL", ""))
A255: 257 | B255: 257_C006 | C255: SIT API URL | D255: UAT API URL | E255: PROD API URL | G255: https://videocenter-uat.sinopac.com:8080/VCS/restful/custWaiting | H255: https://videocenter.sinopac.com:8080/VCS/restful/custWaiting | I255: =IF(ISERROR(F255), "缺SIT API URL", IF(F255=0, "缺SIT API URL", "")) -> 缺SIT API URL | J255: =IF(ISERROR(G255), "缺UAT API URL", IF(G255=0, "缺UAT API URL", "")) | K255: =IF(ISERROR(H255), "缺PROD API URL", IF(H255=0, "缺PROD API URL", ""))
A256: 258 | B256: 258_C007 | C256: SIT API URL | D256: UAT API URL | E256: PROD API URL | G256: https://videocenter-uat.sinopac.com:8080/VCS/restful/custCancelCall | H256: https://videocenter.sinopac.com:8080/VCS/restful/custCancelCall | I256: =IF(ISERROR(F256), "缺SIT API URL", IF(F256=0, "缺SIT API URL", "")) -> 缺SIT API URL | J256: =IF(ISERROR(G256), "缺UAT API URL", IF(G256=0, "缺UAT API URL", "")) | K256: =IF(ISERROR(H256), "缺PROD API URL", IF(H256=0, "缺PROD API URL", ""))
A257: 259 | B257: 259_C008 | C257: SIT API URL | D257: UAT API URL | E257: PROD API URL | G257: https://videocenter-uat.sinopac.com:8080/VCS/restful/reportAgentDisconnected | H257: https://videocenter.sinopac.com:8080/VCS/restful/reportAgentDisconnected | I257: =IF(ISERROR(F257), "缺SIT API URL", IF(F257=0, "缺SIT API URL", "")) -> 缺SIT API URL | J257: =IF(ISERROR(G257), "缺UAT API URL", IF(G257=0, "缺UAT API URL", "")) | K257: =IF(ISERROR(H257), "缺PROD API URL", IF(H257=0, "缺PROD API URL", ""))
A258: 260 | B258: 260_C009 | C258: SIT API URL | D258: UAT API URL | E258: PROD API URL | G258: https://videocenter-uat.sinopac.com:8080/VCS/restful/vidyoLoginValidate | H258: https://videocenter.sinopac.com:8080/VCS/restful/vidyoLoginValidate | I258: =IF(ISERROR(F258), "缺SIT API URL", IF(F258=0, "缺SIT API URL", "")) -> 缺SIT API URL | J258: =IF(ISERROR(G258), "缺UAT API URL", IF(G258=0, "缺UAT API URL", "")) | K258: =IF(ISERROR(H258), "缺PROD API URL", IF(H258=0, "缺PROD API URL", ""))
A259: 261 | B259: 261_C010 | C259: SIT API URL | D259: UAT API URL | E259: PROD API URL | F259: http://10.11.36.37:808/AppService/WebServices/ws_UserStatusQuery.ashx | G259: http://10.11.42.80:808/AppService/WebServices/ws_UserStatusQuery.ashx | H259: http://10.15.1.55:808/AppService/WebServices/ws_UserStatusQuery.ashx | I259: =IF(ISERROR(F259), "缺SIT API URL", IF(F259=0, "缺SIT API URL", "")) | J259: =IF(ISERROR(G259), "缺UAT API URL", IF(G259=0, "缺UAT API URL", "")) | K259: =IF(ISERROR(H259), "缺PROD API URL", IF(H259=0, "缺PROD API URL", ""))
A260: 262 | B260: 262_C011 | C260: SIT API URL | D260: UAT API URL | E260: PROD API URL | F260: http://10.11.36.36/MemberPortal/Member/ProxyLogin.ashx | G260: http://10.11.42.235/MemberPortal/Member/ProxyLogin.ashx | H260: https://mma.sinopac.com/MemberPortal/Member/ProxyLogin.ashx | I260: =IF(ISERROR(F260), "缺SIT API URL", IF(F260=0, "缺SIT API URL", "")) | J260: =IF(ISERROR(G260), "缺UAT API URL", IF(G260=0, "缺UAT API URL", "")) | K260: =IF(ISERROR(H260), "缺PROD API URL", IF(H260=0, "缺PROD API URL", ""))
...

Sheet 0714更新
A1: No | B1: Dept 部別 | C1: Team 科別 | D1: SysCode 應用系統代碼 | E1: SysName 中文應用系統名稱 | F1: Sys English Name | G1: API Code API代碼
A2: 55 | B2: 商品應用部 | C2: 財富信託科 | D2: TWTXN00073 | E2: 智能理財系統 | F2: ibrain | G2: Inv001_A | H2: =_xlfn.CONCAT(A2,"_",G2) -> 55_Inv001_A | I2: Y | J2: Y
A3: 56 | B3: 商品應用部 | C3: 財富信託科 | D3: TWTXN00073 | E3: 智能理財系統 | F3: ibrain | G3: Inv002_A | H3: =_xlfn.CONCAT(A3,"_",G3) -> 56_Inv002_A | I3: Y | J3: Y
A4: 57 | B4: 商品應用部 | C4: 財富信託科 | D4: TWTXN00073 | E4: 智能理財系統 | F4: ibrain | G4: Inv003_A | H4: =_xlfn.CONCAT(A4,"_",G4) -> 57_Inv003_A | I4: Y | J4: Y
A5: 58 | B5: 商品應用部 | C5: 財富信託科 | D5: TWTXN00073 | E5: 智能理財系統 | F5: ibrain | G5: Inv004_A | H5: =_xlfn.CONCAT(A5,"_",G5) -> 58_Inv004_A | I5: Y | J5: Y
A6: 59 | B6: 商品應用部 | C6: 財富信託科 | D6: TWTXN00073 | E6: 智能理財系統 | F6: ibrain | G6: Inv005_A | H6: =_xlfn.CONCAT(A6,"_",G6) -> 59_Inv005_A | I6: Y | J6: Y
A7: 60 | B7: 商品應用部 | C7: 財富信託科 | D7: TWTXN00073 | E7: 智能理財系統 | F7: ibrain | G7: Inv006_A | H7: =_xlfn.CONCAT(A7,"_",G7) -> 60_Inv006_A | I7: Y | J7: Y
A8: 61 | B8: 商品應用部 | C8: 財富信託科 | D8: TWTXN00073 | E8: 智能理財系統 | F8: ibrain | G8: Inv007_A | H8: =_xlfn.CONCAT(A8,"_",G8) -> 61_Inv007_A | I8: Y | J8: Y
A9: 62 | B9: 商品應用部 | C9: 財富信託科 | D9: TWTXN00073 | E9: 智能理財系統 | F9: ibrain | G9: Inv008_A | H9: =_xlfn.CONCAT(A9,"_",G9) -> 62_Inv008_A | I9: Y | J9: Y
A10: 63 | B10: 商品應用部 | C10: 財富信託科 | D10: TWTXN00073 | E10: 智能理財系統 | F10: ibrain | G10: Inv009_A | H10: =_xlfn.CONCAT(A10,"_",G10) -> 63_Inv009_A | I10: Y | J10: Y
A11: 64 | B11: 商品應用部 | C11: 財富信託科 | D11: TWTXN00073 | E11: 智能理財系統 | F11: ibrain | G11: Inv010_A | H11: =_xlfn.CONCAT(A11,"_",G11) -> 64_Inv010_A | I11: Y | J11: Y
A12: 65 | B12: 商品應用部 | C12: 財富信託科 | D12: TWTXN00073 | E12: 智能理財系統 | F12: ibrain | G12: Inv011_A | H12: =_xlfn.CONCAT(A12,"_",G12) -> 65_Inv011_A | I12: Y | J12: Y
A13: 66 | B13: 商品應用部 | C13: 財富信託科 | D13: TWTXN00073 | E13: 智能理財系統 | F13: ibrain | G13: Inv012_A | H13: =_xlfn.CONCAT(A13,"_",G13) -> 66_Inv012_A | I13: Y | J13: Y
... A156: 209 | B156: 商品應用部 | C156: 財富信託科 | D156: BS09040 | E156: 財富交易OBU基金網銀系統 | F156: OBU | G156: Inv25_O | H156: =_xlfn.CONCAT(A156,"_",G156) -> 209_Inv25_O | I156: Y | J156: Y
A157: 267 | B157: 金融技術部 | C157: 資料庫應用科 | D157: BS09050 | E157: 新客戶關係暨財富管理系統 | F157: NCRM | G157: CheckCifEtfFg | H157: 267_CrossSaleCheck | I157: Y | J157: 267_CrossSaleCheck
A158: 268 | B158: 金融技術部 | C158: 資料庫應用科 | D158: BS09050 | E158: 新客戶關係暨財富管理系統 | F158: NCRM | G158: UpdateCifEtfFg | H158: 268_CrossSaleUpdate | I158: Y | J158: 268_CrossSaleUpdate
A159: 269 | B159: 金融技術部 | C159: 資料庫應用科 | D159: BS09050 | E159: 新客戶關係暨財富管理系統 | F159: NCRM | G159: RiskTest | H159: 269_InvProfileCalculate | I159: Y | J159: 269_InvProfileCalculate
A160: 270 | B160: 金融技術部 | C160: 資料庫應用科 | D160: BS09050 | E160: 新客戶關係暨財富管理系統 | F160: NCRM | G160: RiskTestConfirm | H160: 270_InsCusInvQuestionnaire | I160: Y | J160: 270_InsCusInvQuestionnaire
A161: 271 | B161: 金融技術部 | C161: 資料庫應用科 | D161: BS09050 | E161: 新客戶關係暨財富管理系統 | F161: NCRM | G161: GetD_Risk | H161: 271_GetCusFinanceStatus | I161: Y | J161: 271_GetCusFinanceStatus
A162: 272 | B162: 金融技術部 | C162: 資料庫應用科 | D162: BS09050 | E162: 新客戶關係暨財富管理系統 | F162: NCRM | G162: GetPdf | H162: 272_GetCusKYC | I162: Y | J162: 272_GetCusKYC
A163: 292 | B163: 商品應用部 | C163: 財富信託科 | D163: TWTXN00059 | E163: 財富交易網銀系統 | F163: iFund | G163: Inv104_F | H163: =_xlfn.CONCAT(A163,"_",G163) -> 292_Inv104_F | I163: Y | J163: Y
A164: 293 | B164: 商品應用部 | C164: 財富信託科 | D164: TWTXN00059 | E164: 財富交易網銀系統 | F164: iFund | G164: Inv105_F | H164: =_xlfn.CONCAT(A164,"_",G164) -> 293_Inv105_F | I164: Y | J164: Y
A165: 298 | B165: 商品應用部 | C165: 財富信託科 | D165: TWTXN00092 | E165: 信託後台API服務 | F165: iTrust | G165: Inv003_T | H165: =_xlfn.CONCAT(A165,"_",G165) -> 298_Inv003_T | I165: Y | J165: Y
A166: 299 | B166: 商品應用部 | C166: 財富信託科 | D166: TWTXN00092 | E166: 信託後台API服務 | F166: iTrust | G166: Inv004_T | H166: =_xlfn.CONCAT(A166,"_",G166) -> 299_Inv004_T | I166: Y | J166: Y
A167: 300 | B167: 商品應用部 | C167: 財富信託科 | D167: TWTXN00092 | E167: 信託後台API服務 | F167: iTrust | G167: Inv005_T | H167: =_xlfn.CONCAT(A167,"_",G167) -> 300_Inv005_T | I167: Y | J167: Y
A168: 301 | B168: 商品應用部 | C168: 財富信託科 | D168: TWTXN00092 | E168: 信託後台API服務 | F168: iTrust | G168: Inv006_T | H168: =_xlfn.CONCAT(A168,"_",G168) -> 301_Inv006_T | I168: Y | J168: Y
A169: 302 | B169: 商品應用部 | C169: 財富信託科 | D169: TWTXN00092 | E169: 信託後台API服務 | F169: iTrust | G169: Inv007_T | H169: =_xlfn.CONCAT(A169,"_",G169) -> 302_Inv007_T | I169: Y | J169: Y
A170: 303 | B170: 商品應用部 | C170: 財富信託科 | D170: TWTXN00092 | E170: 信託後台API服務 | F170: iTrust | G170: Inv008_T | H170: =_xlfn.CONCAT(A170,"_",G170) -> 303_Inv008_T | I170: Y | J170: Y
A171: 304 | B171: 商品應用部 | C171: 財富信託科 | D171: TWTXN00092 | E171: 信託後台API服務 | F171: iTrust | G171: Inv009_T | H171: =_xlfn.CONCAT(A171,"_",G171) -> 304_Inv009_T | I171: Y | J171: Y
A172: 305 | B172: 商品應用部 | C172: 財富信託科 | D172: TWTXN00092 | E172: 信託後台API服務 | F172: iTrust | G172: Inv010_T | H172: =_xlfn.CONCAT(A172,"_",G172) -> 305_Inv010_T | I172: Y | J172: Y
A173: 318 | B173: 金融技術部 | C173: 資料庫應用科 | D173: BS09050 | E173: 新客戶關係暨財富管理系統 | F173: NCRM | G173: GetCusRiskMsg | H173: =_xlfn.CONCAT(A173,"_",G173) -> 318_GetCusRiskMsg | I173: Y | J173: Y
A174: 319 | B174: 金融技術部 | C174: 資料庫應用科 | D174: BS09050 | E174: 新客戶關係暨財富管理系統 | F174: NCRM | G174: GetKYCQuestion | H174: =_xlfn.CONCAT(A174,"_",G174) -> 319_GetKYCQuestion | I174: Y | J174: Y
... A231: 424 | B231: 商品應用部 | C231: 財富信託科 | D231: TWTXN00073 | E231: 智能理財系統 | F231: ibrain | G231: Inv058_A | H231: =_xlfn.CONCAT(A231,"_",G231) -> 424_Inv058_A | I231: Y | J231: 424_Inv_058_A

Sheet 0721更新
D1: sheetname
A2: NCRM | B2: GetCusRiskMsg | C2: funGetCusRiskMsg | D2: =VLOOKUP(B2,'0714更新'!G:H,2,FALSE) -> 318_GetCusRiskMsg
A3: NCRM | B3: GetKYCQuestion | C3: funGetKYCQuestion | D3: =VLOOKUP(B3,'0714更新'!G:H,2,FALSE) -> 319_GetKYCQuestion
A4: NCRM | B4: QueTest | C4: funQueTest | D4: =VLOOKUP(B4,'0714更新'!G:H,2,FALSE) -> 320_QueTest
A5: NCRM | B5: QueTestConfirm | C5: funQueTestConfirm | D5: =VLOOKUP(B5,'0714更新'!G:H,2,FALSE) -> 321_QueTestConfirm
A6: NCRM | B6: GetRecommPdf | C6: funGetRecommPdf | D6: =VLOOKUP(B6,'0714更新'!G:H,2,FALSE) -> 322_GetRecommPdf
A7: NCRM | B7: GetFundRankings | C7: funGetFundRankings | D7: =VLOOKUP(B7,'0714更新'!G:H,2,FALSE) -> 323_GetFundRankings
A8: NCRM | B8: GetCusGolds | C8: funGetCusGolds | D8: =VLOOKUP(B8,'0714更新'!G:H,2,FALSE) -> 324_GetCusGolds
A9: OBU | B9: Inv11_O | C9: Qry040O | D9: =VLOOKUP(B9,'0714更新'!G:H,2,FALSE) -> 384_Inv11_O
A10: OBU | B10: Inv21_O | C10: Qry010O | D10: =VLOOKUP(B10,'0714更新'!G:H,2,FALSE) -> 394_Inv21_O
A11: OBU | B11: Inv13_O | C11: Tx045O | D11: =VLOOKUP(B11,'0714更新'!G:H,2,FALSE) -> 386_Inv13_O
A12: iFund | B12: Inv001_F | C12: funGetAllCertificate | D12: =VLOOKUP(B12,'0714更新'!G:H,2,FALSE) -> 104_Inv001_F
A13: iFund | B13: Inv069_F | C13: funconfirmSwitchRecord | D13: =VLOOKUP(B13,'0714更新'!G:H,2,FALSE) -> 172_Inv069_F
... A32: iTrust | B32: Inv010_T | C32: funGetSompanystockSum | D32: =VLOOKUP(B32,'0714更新'!G:H,2,FALSE) -> 305_Inv010_T

Sheet 0728更新
D1: sheetname
A2: iFund | B2: Inv072_F | C2: funCreateAirGeneralRecord | D2: =VLOOKUP(B2,'0714更新'!G:H,2,FALSE) -> 175_Inv072_F
A3: iFund | B3: Inv074_F | C3: funCreateAirAutoRecord | D3: =VLOOKUP(B3,'0714更新'!G:H,2,FALSE) -> 177_Inv074_F
A4: iFund | B4: Inv076_F | C4: funCreateAirRedemRecord | D4: =VLOOKUP(B4,'0714更新'!G:H,2,FALSE) -> 179_Inv076_F
A5: iFund | B5: Inv078_F | C5: funCreateAirSwitchRecord | D5: =VLOOKUP(B5,'0714更新'!G:H,2,FALSE) -> 181_Inv078_F
A6: iFund | B6: Inv080_F | C6: funJCreateAirEIMSubsRecord | D6: =VLOOKUP(B6,'0714更新'!G:H,2,FALSE) -> 183_Inv080_F
A7: iFund | B7: Inv082_F | C7: funJ_CreateAirBondRedemRecord | D7: =VLOOKUP(B7,'0714更新'!G:H,2,FALSE) -> 185_Inv082_F
A8: iFund | B8: Inv085_F | C8: funJ_CreateBondSubsRecord | D8: =VLOOKUP(B8,'0714更新'!G:H,2,FALSE) -> 188_Inv085_F
A9: iFund | B9: Inv087_F | C9: funJ_CreateBondRedemRecord | D9: =VLOOKUP(B9,'0714更新'!G:H,2,FALSE) -> 190_Inv087_F
A10: iFund | B10: Inv102_F | C10: funJ_ConfirmAirBondSubsRecord | D10: =VLOOKUP(B10,'0714更新'!G:H,2,FALSE) -> 191_Inv102_F
A11: iFund | B11: Inv103_F | C11: funJ_CreateAirBondSubsRecord | D11: =VLOOKUP(B11,'0714更新'!G:H,2,FALSE) -> 192_Inv103_F
A12: iFund | B12: Inv104_F | C12: funConfirmAirGainLoss | D12: =VLOOKUP(B12,'0714更新'!G:H,2,FALSE) -> 292_Inv104_F
A13: iFund | B13: Inv105_F | C13: funCreateAirGainLoss | D13: =VLOOKUP(B13,'0714更新'!G:H,2,FALSE) -> 293_Inv105_F
... A19: ibrain | B19: Inv028_A | C19: 確認資產再平衡交易 | D19: =VLOOKUP(B19,'0714更新'!G:H,2,FALSE) -> 82_Inv028_A

Sheet Summary
B2: TW IB/MB API List
B3: ='API Index'!B2 -> Version: | C3: ='API Index'!C2 -> 45471 | E3: No | F3: (多重項目)
I4: No | J4: (全部)
B5: Dept/Team/System | C5: 計數 - No | E5: 部/科/System | F5: 計數 - API Code API代碼
B6: 商品應用部 | C6: 210 | E6: 營運應用部 | F6: 1 | H6: 已回覆 | I6: 計數 - No | J6: Customer Transaction related | N6: Interface Contact Window
B7: 金融市場科 | C7: 6 | E7: 徵審應用科 | F7: 1 | H7: 45002 | I7: Dept/Team | J7: Callee | K7: Caller | L7: SSO | M7: 總計 | N7: Main Owner | O7: Proxy
B8: ETS | C8: 4 | E8: LoanApply | F8: 1 | I8: 金融技術部 | J8: 28 | M8: 28
B9: FOREX | C9: 2 | E9: 數位應用部 | F9: 19 | H9: v | I9: 架構應用科 | J9: 8 | M9: 8 | N9: 梁志偉 | O9: 林威佑
B10: 信用支付科 | C10: 11 | E10: 自助交易科 | F10: 5 | H10: v | I10: 資料庫應用科 | J10: 20 | M10: 20 | N10: 黃智剛 | O10: 林琬婷
B11: EWEB | C11: 11 | E11: FEP | F11: 5 | I11: 數位應用部 | J11: 81 | K11: 30 | L11: 2 | M11: 113
B12: 財富信託科 | C12: 193 | E12: 行動應用科 | F12: 1 | H12: v | I12: TST | K12: 13 | M12: 13 | N12: 梁志偉 | O12: 謝佩錡
B13: ETF | C13: 37 | E13: iBranch | F13: 1 | H13: v | I13: 企網平台科 | J13: 5 | K13: 6 | L13: 1 | M13: 12 | N13: 郭思廷 | O13: 吳文瑞
B14: ibrain | C14: 49 | E14: 數支應用科 | F14: 13 | H14: v | I14: 自助交易科 | J14: 24 | M14: 24 | N14: 楊勝富 | O14: 邱子芸
B15: iFund | C15: 101 | E15: PayBill | F15: 11 | H15: v | I15: 行動應用科 | J15: 5 | M15: 5 | N15: 喻璽 | O15: 吳育慶
B16: iTrust | C16: 4 | E16: BSPSearch | F16: 2 | H16: v | I16: 個網平台科 | J16: 4 | M16: 4 | N16: 賴怡婷 | O16: 林素娟
B17: OBU | C17: 1 | E17: 商品應用部 | F17: 89 | H17: v | I17: 通路應用科 | J17: 21 | K17: 5 | M17: 26 | N17: 黃國堂 | O17: 林彥良
B18: INS | C18: 1 | E18: 金融市場科 | F18: 12 | I18: 數支應用科 | J18: 22 | K18: 6 | L18: 1 | M18: 29 | N18: 汪冠宏 | O18: 翁岳駿
B19: 金融技術部 | C19: 8 | E19: TPSPS | F19: 2 | H19: v | I19: 永豐金證券 -系統開發一部 | J19: 5 | M19: 5
B20: 架構應用科 | C20: 2 | E20: HKSPS | F20: 2 | I20: 電子交易科 | J20: 5 | M20: 5 | N20: 卓崇聖 | O20: 喻璽
B21: TWIDPortal | C21: 2 | E21: MXREP | F21: 4 | H21: v | I21: 核心應用部 | J21: 4 | M21: 4
B22: 資料庫應用科 | C22: 6 | E22: Gold Business Systematic Investment Plan System | F22: 4 | H22: v | I22: 放款外匯科 | J22: 3 | M22: 3 | N22: 陳東隆 | O22: 施宗佑
B23: NCRM | C23: 6 | E23: 信用支付科 | F23: 13 | I23: 核心規劃科 | J23: 1 | M23: 1 | N23: 游鯉菁 | O23: 陳睿緯
B24: 核心應用部 | C24: 3 | E24: EWEB | F24: 13 | H24: v | I24: 商品應用部 | J24: 339 | M24: 339
B25: 放款外匯科 | C25: 3 | E25: 財富信託科 | F25: 64 | H25: v | I25: 金融市場科 | J25: 19 | M25: 19 | N25: 陶惟傑 | O25: 許南妮
B26: VISA DIRECT | C26: 3 | E26: ETF | F26: 4 | H26: v | I26: 信用支付科 | J26: 36 | M26: 36 | N26: 邵方明 | O26: 吳紫瑜
B27: 數位應用部 | C27: 53 | E27: ibrain | F27: 4 | I27: 財富信託科 | J27: 284 | M27: 284 | N27: 謝佩錡 | O27: 黃嘉皇
B28: 企網平台科 | C28: 11 | E28: iFund | F28: 20 | H28: v | I28: 營運應用部 | J28: 7 | M28: 7
B29: EAINET | C29: 1 | E29: iTrust | F29: 8 | H29: v | I29: 平台應用科 | J29: 1 | M29: 1 | N29: 蔡秋汶 | O29: 翁淑婉
B30: EVENTSITE | C30: 4 | E30: OBU | F30: 24 | H30: v | I30: 徵審應用科 | J30: 3 | M30: 3 | N30: 曾宏善 | O30: 廖萍志
B31: MMAB2B | C31: 6 | E31: INSAG | F31: 4 | I31: 營運發展科 | J31: 3 | M31: 3 | N31: 魏品軒 | O31: 賴佳慧
B32: 自助交易科 | C32: 16 | E32: 核心應用部 | F32: 1 | I32: 總計 | J32: 464 | K32: 30 | L32: 2 | M32: 496
B33: FEP | C33: 8 | E33: 核心規劃科 | F33: 1
B34: SMTP | C34: 8 | E34: ACCT_NTFY | F34: 1
B35: 個網平台科 | C35: 4 | E35: 金融技術部 | F35: 8
B36: AuthCenter | C36: 1 | E36: 架構應用科 | F36: 1
B37: FundInfo | C37: 3 | E37: LINE BC | F37: 1
B38: 通路應用科 | C38: 15 | E38: 資料庫應用科 | F38: 7
B39: BILLHUNTER | C39: 1 | E39: NCRM | F39: 7
B40: Branch | C40: 3 | E40: 永豐金證券 -系統開發一部 | F40: 5
B41: CSS | C41: 2 | E41: 電子交易科 | F41: 5
...

Sheet Callee Progress
B1: ='API Index'!B2 -> Version: | C1: ='API Index'!C2 -> 45471
B2: Alive 維運中 | C2: (多重項目)
C4: Type
C5: 計數 - No | D5: DEV/UT Rate | E5: 計數 - No 的加總 | F5: DEV/UT Rate 的加總 | I5: Interface Contact Window
B6: Dept部/Section科 | C6: Callee | D6: Callee | I6: Main Owner | J6: Proxy
B7: 核心應用部 | C7: 4 | D7: 1 | E7: 4 | F7: 1
B8: 放款外匯科 | C8: 3 | D8: 1 | E8: 3 | F8: 1
B9: 核心規劃科 | C9: 1 | D9: 1 | E9: 1 | F9: 1
B10: 商品應用部 | C10: 331 | D10: 1 | E10: 331 | F10: 1
B11: 金融市場科 | C11: 17 | D11: 1 | E11: 17 | F11: 1
B12: 信用支付科 | C12: 36 | D12: 1 | E12: 36 | F12: 1
B13: 財富信託科 | C13: 278 | D13: 1 | E13: 278 | F13: 1
B14: 金融技術部 | C14: 28 | D14: 1 | E14: 28 | F14: 1
B15: 架構應用科 | C15: 8 | D15: 1 | E15: 8 | F15: 1
B16: 資料庫應用科 | C16: 20 | D16: 1 | E16: 20 | F16: 1
B17: 數位應用部 | C17: 70 | D17: 1 | E17: 70 | F17: 1
B18: 企網平台科 | C18: 2 | D18: 1 | E18: 2 | F18: 1
... B30: 總計 | C30: 445 | D30: 1 | E30: 445 | F30: 1

Sheet 工作表4
A1: API collection | B1: (多重項目)
A3: 列標籤 | B3: 計數 - API Code API代碼
A4: 總計

Sheet Caller API
B1: ='Callee Progress'!B1 -> Version: | C1: ='Callee Progress'!C1 -> 45471
B5: Caller API 開發單測進度 : | E5: =AVERAGE(H8:H30) -> 1 | I5: YYYY/MM/DD
I6: 開發單測完成日
B7: Dept 部別 | C7: Team 科別 | D7: Type | E7: SysName / DB AccountName | F7: SysOwner | G7: Phase | H7: Dev完成率 | I7: Dev/UT Date | J7: Caller/Callee | K7: Expose API Name | L7: Remark 備註 | M7: API No. | N7: API Code API代碼 | O7: API Section API中英文名稱 | P7: Description API中文說明
A8: 1 | B8: 金融技術部 | C8: 架構應用科 | D8: 即時交易推播 | E8: 身分認證中心 | F8: 梁志偉 | G8: P1 | H8: 1 | I8: 45382 | J8: Caller | K8: PushNotification | L8: 系統呼叫網行銀 | X8: DeepLink
A9: 2 | B9: 數位應用部 | C9: 自助交易科 | D9: 即時交易推播 | E9: FEP跨行前置系統 | F9: 謝汰嵻 | G9: P1 | H9: 1 | I9: 45289 | J9: Caller | K9: PushNotification | L9: 系統呼叫網行銀 | M9: 227 | N9: NWC | O9: 關閉無卡提款(推播部分) | P9: 關閉無卡提款(推播部分)_狀態更新 | X9: SSOAuthentication
A10: 3 | B10: 數位應用部 | C10: 自助交易科 | D10: 即時交易推播 | E10: FEP無卡提款 | F10: 謝汰嵻 | G10: P1 | H10: 1 | I10: 45260 | J10: Caller | K10: CardlessWithdraw | L10: 系統呼叫網行銀 | M10: N/A | N10: ATM上的交易 | O10: 無卡提款 (ATM) | P10: 無卡提款(推播通知) | X10: getCustomerInfo
A11: 4 | B11: 金融技術部 | C11: 架構應用科 | D11: 即時交易推播 | E11: 開放API服務系統 | F11: 李騫政 | G11: P1 | H11: 1 | I11: 45382 | J11: Caller | K11: PushNotification | L11: 系統呼叫網行銀 | X11: CardlessWithdraw
A12: 5 | B12: 核心應用部 | C12: 核心規劃科 | D12: 即時交易推播 | E12: T24帳務訊息通知 | F12: 游鯉菁 | G12: P1 | H12: 1 | I12: 45322 | J12: Caller | K12: PushNotification | L12: 系統呼叫網行銀 | X12: SpecialRevolvingLoan
A13: 6 | B13: 商品應用部 | C13: 財富信託科 | D13: 即時交易推播 | E13: 美股/ETF | F13: 陳琦龍 | G13: P1 | H13: 1 | I13: 45351 | J13: Caller | K13: PushNotification | L13: 系統呼叫網行銀 | X13: PushNotification
A14: 7 | B14: 商品應用部 | C14: 財富信託科 | D14: 即時交易推播 | E14: 空地對接 | F14: 陳琦龍 | G14: P1 | H14: 1 | I14: 45351 | J14: Caller | K14: PushNotification | L14: 系統呼叫網行銀 | X14: ShoppingCartFundID
A15: 8 | B15: 金融技術部 | C15: 資料庫應用科 | D15: 批次交易推播 | E15: UnicaUser (DB) | F15: 楊雅慧 | G15: P1 | H15: 1 | I15: 45596 | J15: Caller | K15: PushNotification | L15: 系統呼叫網行銀 | X15: WatchList
A16: 9 | B16: 商品應用部 | C16: 財富信託科 | D16: 批次交易推播 | E16: ai_user (DB) | F16: 謝佩錡 | G16: P1 | H16: 1 | I16: 45351 | J16: Caller | K16: PushNotification | L16: 系統呼叫網行銀 | X16: sendVideoVerifyResult
A17: 10 | B17: 商品應用部 | C17: 財富信託科 | D17: 批次交易推播 | E17: ddsc (DB) | F17: 李佳欣 | G17: P1 | H17: 1 | I17: 45382 | J17: Caller | K17: PushNotification | L17: 系統呼叫網行銀
A18: 11 | B18: 證券系統開發一部 | C18: 電子交易科 | D18: 證券便利金 | E18: 大戶投APP | F18: 卓崇聖 | G18: P1 | H18: 1 | I18: 45443 | J18: Caller | K18: SpecialRevolvingLoan | L18: 系統呼叫網行銀
A19: 12 | B19: 數位應用部 | C19: 數支應用科 | D19: 即時交易推播 | E19: O2O金流服務系統 | F19: 賴長春 | G19: P1 | H19: 1 | I19: 45289 | J19: Caller | K19: PushNotification | L19: 系統呼叫網行銀 | M19: 439 | N19: PushNotification | O19: PushNotification | P19: funlink推播發送
A20: 13 | B20: 數位應用部 | C20: 個網平台科 | D20: 基金購物車 | E20: 基金資訊源(新理財資訊網) | F20: 林如瑩 | G20: P1 | H20: 1 | I20: 45322 | J20: Caller | K20: getShoppingCartFundID | L20: 系統呼叫網行銀 | M20: 476 | N20: getShoppingCartFundID | O20: getShoppingCartFundID | P20: getShoppingCartFundID
A21: 14 | B21: 數位應用部 | C21: 個網平台科 | D21: 基金購物車 | E21: 基金資訊源(新理財資訊網) | F21: 林如瑩 | G21: P1 | H21: 1 | I21: 45322 | J21: Caller | K21: updateShopingCartFundID | L21: 系統呼叫網行銀 | M21: 477 | N21: updateShopingCartFundID | O21: updateShopingCartFundID | P21: updateShopingCartFundID
A22: 15 | B22: 數位應用部 | C22: 個網平台科 | D22: 觀察清單 | E22: 基金資訊源(新理財資訊網) | F22: 林如瑩 | G22: P1 | H22: 1 | I22: 45322 | J22: Caller | K22: getWatchList | L22: 系統呼叫網行銀 | M22: 478 | N22: getWatchList | O22: getWatchList | P22: getWatchList
A23: 16 | B23: 數位應用部 | C23: 個網平台科 | D23: 觀察清單 | E23: 基金資訊源(新理財資訊網) | F23: 林如瑩 | G23: P1 | H23: 1 | I23: 45322 | J23: Caller | K23: saveWatchList | L23: 系統呼叫網行銀 | M23: 479 | N23: saveWatchList | O23: saveWatchList | P23: saveWatchList
A24: 17 | B24: 數位應用部 | C24: 通路應用科 | D24: 即時交易推播 | E24: 客服中心網路電話系統 | F24: 蔡騰輝 | G24: P1 | H24: 1 | I24: 45382 | J24: Caller | K24: PushNotification | L24: 系統呼叫網行銀
A25: 18 | B25: 數位應用部 | C25: 通路應用科 | D25: 視訊驗證結果 | E25: 客服中心網路電話系統 | F25: 蔡騰輝 | G25: P1 | H25: 1 | I25: 45289 | J25: Caller | K25: sendVideoVerifyResult | L25: 系統呼叫網行銀
A26: 19 | B26: 金融技術部 | C26: 資料庫應用科 | D26: 即時交易推播 | E26: 點數管理系統 | F26: 何欣蓓 | G26: P1 | H26: 1 | I26: 45473 | J26: Caller | K26: PushNotification | L26: 系統呼叫網行銀
A27: 20 | B27: 金融技術部 | C27: 資料庫應用科 | D27: 批次交易推播 | E27: 點數管理系統 | F27: 何欣蓓 | G27: P1 | H27: 1 | I27: 45443 | J27: Caller | K27: PushNotification | L27: 系統呼叫網行銀
A28: 21 | B28: 商品應用部 | C28: 信用支付科 | D28: 即時交易推播 | E28: 信用卡營運系統 | F28: 邵方明 | G28: P1 | H28: 1 | I28: 45322 | J28: Caller | K28: PushNotification | L28: 信用卡/簽帳金融卡即時消費通知
A29: 22 | B29: 商品應用部 | C29: 信用支付科 | D29: 即時交易推播 | E29: 信用卡營運系統 | F29: 邵方明 | G29: P1 | H29: 1 | I29: 45322 | J29: Caller | K29: PushNotification | L29: 信用卡帳單設定異動通知
A30: 23 | B30: 數位應用部 | C30: 數支應用科 | D30: 即時交易推播 | E30: 繳費網 | F30: 紀緯霖 | G30: P1 | H30: 1 | I30: 45289 | J30: Caller | K30: PushNotification | L30: 系統呼叫網行銀 | N30: RealTimePushNotification | O30: RealTimePushNotification | P30: 票交交易退款/取消推播發送
A31: 1 | B31: 金融技術部 | C31: 架構應用科 | D31: 網銀身分認證 | E31: APIM管理系統 | F31: 李騫政 | G31: P1 | H31: 1 | I31: 45382 | J31: Caller | K31: DeepLink | L31: 關聯系統
A32: 1 | B32: 數位應用部 | C32: 通路應用科 | D32: 網銀身分認證 | E32: 分行系統(Branch System) | F32: 林彥良 | G32: P2 | H32: 0 | J32: Caller | L32: 第一階段MMA還會在，所以分行系統呼叫的WCF不會變動，第二階段MMA也要換到新平台，所以提供給分行系統呼叫的WCF會調整成API的形式 | M32: 263 | N32: C012 | O32: 啟用網銀 Apply MMA | P32: 數位、雲端開戶啟用網銀
A33: 2 | B33: 數位應用部 | C33: 通路應用科 | D33: 網銀客戶查詢 | E33: 分行系統(Branch System) | F33: 林彥良 | G33: P2 | H33: 0 | J33: Caller | L33: 第一階段MMA還會在，所以分行系統呼叫的WCF不會變動，第二階段MMA也要換到新平台，所以提供給分行系統呼叫的WCF會調整成API的形式 | M33: 264 | N33: C013 | O33: MMA客戶狀態查詢、變更、新增 Inquery、Update、Add MMA Member Status | P33: MMA客戶狀態查詢、變更、新增 Inquery、Update、Add MMA Member Status
A34: 3 | B34: 數位應用部 | C34: 通路應用科 | D34: 網銀身分認證 | E34: 作業自動化中台 | F34: 魏金龍 | G34: P2 | H34: 0 | J34: Caller | L34: 第一階段MMA還會在，所以分行系統呼叫的WCF不會變動，第二階段MMA也要換到新平台，所以提供給分行系統呼叫的WCF會調整成API的形式 | M34: 418 | N34: C015 | O34: 啟用網銀 Apply MMA | P34: 數位、雲端開戶啟用網銀
A35: 4 | B35: 數位應用部 | C35: 數支應用科 | E35: 網路ATM3.0 | F35: 紀緯霖 | G35: P2 | H35: 0 | J35: Caller | M35: 425 | N35: IsSinoPacIP | O35: IsSinoPacIP | P35: 判斷是否以非行員身份在內部IP登入
A36: 5 | B36: 數位應用部 | C36: 數支應用科 | E36: 網路ATM3.0 | F36: 紀緯霖 | G36: P2 | H36: 0 | J36: Caller | M36: 426 | N36: TxnDetail | O36: TxnDetail | P36: 往來明細查詢
A37: 6 | B37: 數位應用部 | C37: 數支應用科 | E37: 豐收款 | F37: 張時達 | G37: P2 | H37: 0 | J37: Caller | M37: 427 | N37: MMALogin | O37: MMALogin | P37: MMA登入驗證
A38: 7 | B38: 數位應用部 | C38: 數支應用科 | E38: 豐收款 | F38: 田亦凡 | G38: P2 | H38: 0 | J38: Caller | M38: 428 | N38: IsMMA | O38: IsMMA | P38: 是否為MMA會員
A39: 8 | B39: 數位應用部 | C39: 數支應用科 | E39: 大咖App | F39: 張時達 | G39: P2 | H39: 0 | J39: Caller | M39: 429 | N39: G0102 | O39: G0102 | P39: ID 歸戶資料
C54: Phase 1 Infinity Exposed API Index List
B55: No | C55: Expose API Name | D55: Description | E55: Batch | F55: Start Date | G55: End Date | H55: Plan DeliveryDate | I55: Actual DeliveryDate
B56: 1 | C56: checkIP | D56: When the user logs in to MMA, we need to check if the user is in SinoPac IP, and if so, check if the login ID is of staff or not. If not, do not log the user in. | E56: Batch 2 | F56: 45170 | G56: 45189 | H56: 45191
B57: 2 | C57: SSO | D57: To enables users to securely authenticate with multiple applications and websites by using just one set of SSO token | E57: Batch 2 | F57: 45170 | G57: 45189 | H57: 45191
...

Sheet API Index
B2: Version: | C2: 45471 | F2: API 目錄 Index | N2: 不得晚於2023/12/15
D3: Callee or Caller =行動銀行MB/個網銀MMA/大戶DAWHO | N3: YYYY/MM/DD
L4: 下架日 | N4: 開發單測完成日
B5: No | C5: Dept 部別 | D5: Team 科別 | E5: SysCode 應用系統代碼 | F5: SysName 中文應用系統名稱 | G5: Sys English Name | H5: API Code API代碼 | I5: API Name/Doc Section API中英文名稱 | J5: Description API中文說明 | K5: Alive 維運中 | L5: EndDate 預計下架日(YYYYMMDD) | M5: Dev完成率 | N5: Dev/UT Date | O5: Caller/Callee | P5: Remark 備註 | Q5: Request Content String | R5: Response Content String | S5: API collection | T5: URL待補 | U5: TST Dev% | V5: TST UT%
B6: 001 | C6: 商品應用部 | D6: 金融市場科 | E6: TWTXN00046 | F6: 敲價系統(Electronic Treasury Trading System) | G6: ETS | H6: RequestSpot | I6: 換匯取價 Request FX or GOLD Spot Rate | J6: 換匯取價 RequestSpotRate | K6: Y | M6: 1 | N6: 44927 | O6: Callee | Q6: http://10.11.22.126:886/ETSRateService.asmx/RequestSpot?intSource=8&strKBrNo=769&strRBrNo=006&strBuyCcy=EUR&strSellCcy=USD&decBuyAmt=0&decSellAmt=120000&strXmp=1&strNote=1&strBU=D&strCustId=87654321&strVerify=1001 | R6: <?xml version="1.0" encoding="utf-8" ?> <ReponseSpot> <ReturnRate> <SerialNo>2110007</SerialNo> <RetCode>1</RetCode> <RetMessage>254138556441300708785898874</RetMessage> <VerifyStr>1001</VerifyStr> <ValidSec>35</ValidSec> <TradeDate>2022/08/29 00:00:00</TradeDate> <ValueDate>2022/08/29 00:00:00</ValueDate> <KBrNo>769</KBrNo> <RBrNo>006</RBrNo> <SBrNo>006</SBrNo> <DealNo /> <BuyCcy>EUR</BuyCcy> <BuyAmount>117911.78000</BuyAmount> <SellCcy>USD</SellCcy> <SellAmount>120000.00000</SellAmount> <EmpFlag>1</EmpFlag> <NoteFlag>1</NoteFlag> <BUFlag>D</BUFlag> <TxSelect>1</TxSelect> <TxType>0</TxType> <TxPair>EUR/USD</TxPair> <MidlRate>1.02172</MidlRate> <MrktRate>1.02171</MrktRate> <CostRate>1.02021</CostRate> <ListRate>1.01771</ListRate> <DoneRate>1.01771</DoneRate> <OriginalAmount>120000.00000</OriginalAmount> <EquvUsdAmount>120000.00</EquvUsdAmount> <EquvBaseAmount>3614787.00</EquvBaseAmount> <SettleFlag>1</SettleFlag> <TxRemark /> <CustId>87654321</CustId> <CustName /> <CptyCode /> <AOCode /> <KinUserId /> <KinSUserId /> </ReturnRate> </ReponseSpot>
B7: 002 | C7: 商品應用部 | D7: 金融市場科 | E7: TWTXN00046 | F7: 敲價系統(Electronic Treasury Trading System) | G7: ETS | H7: RequestSpot2 | I7: 換匯取價-優利定存 RequestSpot2 | J7: 換匯取價-優利定存 RequestSpot2 | K7: Y | M7: 1 | N7: 44927 | O7: Callee | Q7: http://10.11.22.126:886/ETSRateService.asmx/RequestSpot2?intSource=8&strKBrNo=769&strRBrNo=006&strBuyCcy=EUR&strSellCcy=USD&decBuyAmt=0&decSellAmt=720000&strXmp=1&strNote=1&strBU=D&strCustId=87654321&strVerify=1002 | R7: <?xml version="1.0" encoding="utf-8" ?> <ReponseSpot> <ReturnRate> <SerialNo>2110012</SerialNo> <RetCode>1</RetCode> <RetMessage>254138556441900708785898874</RetMessage> <VerifyStr>1002</VerifyStr> <ValidSec>45</ValidSec> <TradeDate>2022/08/29 00:00:00</TradeDate> <ValueDate>2022/08/29 00:00:00</ValueDate> <KBrNo>769</KBrNo> <RBrNo>006</RBrNo> <SBrNo>006</SBrNo> <DealNo /> <BuyCcy>EUR</BuyCcy> <BuyAmount>707470.69000</BuyAmount> <SellCcy>USD</SellCcy> <SellAmount>720000.00000</SellAmount> <EmpFlag>1</EmpFlag> <NoteFlag>1</NoteFlag> <BUFlag>D</BUFlag> <TxSelect>1</TxSelect> <TxType>9</TxType> <TxPair>EUR/USD</TxPair> <MidlRate>1.02172</MidlRate> <MrktRate>1.02171</MrktRate> <CostRate>1.02021</CostRate> <ListRate>1.01771</ListRate> <DoneRate>1.01771</DoneRate> <OriginalAmount>720000.00000</OriginalAmount> <EquvUsdAmount>720000.00</EquvUsdAmount> <EquvBaseAmount>21688723.00</EquvBaseAmount> <SettleFlag>1</SettleFlag> <TxRemark /> <CustId>87654321</CustId> <CustName /> <CptyCode /> <AOCode /> <KinUserId /> <KinSUserId /> </ReturnRate> </ReponseSpot>
B8: 003 | C8: 商品應用部 | D8: 金融市場科 | E8: TWTXN00046 | F8: 敲價系統(Electronic Treasury Trading System) | G8: ETS | H8: InsertSpotDeal | I8: 換匯新增成交部位InsertSpotDeal | J8: 換匯新增成交部位InsertSpotDeal | K8: Y | M8: 1 | N8: 44927 | O8: Callee | Q8: http://10.11.22.126:886/ETSRateService.asmx/InsertSpotDeal?intSource=8&strDeal=<?xml version="1.0" encoding="utf-8" ?><ReponseSpot><ReturnRate><SerialNo>2110007</SerialNo><RetCode>1</RetCode><RetMessage>254138556441300708785898874</RetMessage><VerifyStr>1001</VerifyStr><ValidSec>35</ValidSec><TradeDate>2022/08/29</TradeDate><ValueDate>2022/08/29</ValueDate><KBrNo>769</KBrNo><RBrNo>006</RBrNo><SBrNo>006</SBrNo><DealNo /><BuyCcy>EUR</BuyCcy><BuyAmount>117911.78000</BuyAmount><SellCcy>USD</SellCcy><SellAmount>120000.00000</SellAmount><EmpFlag>1</EmpFlag><NoteFlag>1</NoteFlag><BUFlag>D</BUFlag><TxSelect>1</TxSelect><TxType>1</TxType><TxPair>EUR/USD</TxPair><MidlRate>1.02172</MidlRate><MrktRate>1.02171</MrktRate><CostRate>1.02021</CostRate><ListRate>1.01771</ListRate><DoneRate>1.01771</DoneRate><OriginalAmount>120000.00000</OriginalAmount><EquvUsdAmount>120000.00</EquvUsdAmount><EquvBaseAmount>3614787.00</EquvBaseAmount><SettleFlag>1</SettleFlag><TxRemark /><CustId>87654321</CustId><CustName /><CptyCode /><AOCode /><KinUserId>MMA</KinUserId><KinSUserId /></ReturnRate></ReponseSpot> | R8: <?xml version="1.0" encoding="utf-8" ?> <string xmlns="http://ETSWeb.bsp:886/">0829769001</string>
B9: 004 | C9: 商品應用部 | D9: 金融市場科 | E9: TWTXN00046 | F9: 敲價系統(Electronic Treasury Trading System) | G9: ETS | H9: GetReferRate | I9: 換匯參考試算GetReferRate | J9: 換匯參考試算GetReferRate | K9: Y | M9: 1 | N9: 44927 | O9: Callee | Q9: http://10.11.22.126:886//ETSRateService.asmx/GetReferRate?decOriAmt=10000&strFrCcy=USD&strToCcy=TWD | R9: <?xml version="1.0" encoding="utf-8" ?> <ETSSpotDeal> <RefRate> <RetCode>1</RetCode> <RetMessage>OK</RetMessage> <NoteFlag>N</NoteFlag> <CrossRate>29.90000</CrossRate> <OriginalAmount>10000</OriginalAmount> <CrossAmount>299000.00000</CrossAmount> <CrossPair>USD/TWD</CrossPair> <CrossCost>29.94000</CrossCost> <TxPair>USD/TWD</TxPair> <ListBuy>29.90000</ListBuy> <ListSell>30.11000</ListSell> </RefRate> <RefRate> <RetCode>1</RetCode> <RetMessage>OK</RetMessage> <NoteFlag>Y</NoteFlag> <CrossRate>29.70000</CrossRate> <OriginalAmount>10000</OriginalAmount> <CrossAmount>297000.00000</CrossAmount> <CrossPair>USD/TWD</CrossPair> <CrossCost>29.94000</CrossCost> <TxPair>USD/TWD</TxPair> <ListBuy>29.70000</ListBuy> <ListSell>30.31000</ListSell> </RefRate> </ETSSpotDeal>
B10: 005 | C10: 商品應用部 | D10: 金融市場科 | E10: TWTXN00065 | F10: 外幣留單撮合服務(Foreign Exchange Order Service) | G10: FOREX | H10: FUNINSERTFXORDER | I10: 新增留單紀錄(InsertFxOrder) | J10: 新增留單紀錄(InsertFxOrder) | K10: D | M10: 1 | N10: 44927 | O10: Callee | P10: 新網銀說未來不打算保留此功能 | Q10: http://10.11.35.51:8091/FxOrderWebservice.asmx/funFxOrderWS?xmlData= <?xml version="1.0" encoding="UTF-8"?> <GEPS> <RqHeader> <MsgID>FUNINSERTFXORDER</MsgID> <MsgType>G</MsgType> <ChlName>NETBANK</ChlName> <ChlEJNo>MMA-FUNINSERTFXORDER-0002107727917</ChlEJNo> <ChlSendTime>2021/03/12 11:44:16.799</ChlSendTime> <TxnID>V2700</TxnID> <BranchID>SPHNETBANK01</BranchID> <TermID>FXORDER@NETBANK</TermID> <UserID/> <SignID/> </RqHeader> <SvcRq> <Rq> <ExpireDate>20210326</ExpireDate> <KBrNo>769</KBrNo> <RBrNo/> <OriginalAmount>100000.00000</OriginalAmount> <BuyCcy>JPY</BuyCcy> <BuyAmount>100000</BuyAmount> <SellCcy>USD</SellCcy> <SellAmount>0</SellAmount> <BUFlag>D</BUFlag> <TxPair>USD/JPY</TxPair> <QuoteSide>O</QuoteSide> <OrderRate>105</OrderRate> <CustId>A1211114150</CustId> <CustEmail>test@test</CustEmail> <DbAcct>01400800016326</DbAcct> <CrAcct>01400800016326</CrAcct> <DbRemark/> <CrRemark/> </Rq> </SvcRq> </GEPS> | R10: <?xml version="1.0" encoding="utf-8"?> <GEPS> <RsHeader> <RsStat> <RsStatCode>SUCCESS</RsStatCode> <Desc>新增留單成功</Desc> </RsStat> <Overrides><Override /> </Overrides> <ChlEJNo>MMA-FUNINSERTFXORDER-0002107727917</ChlEJNo> <EJNo>MMA-FUNINSERTFXORDER-0002107727917</EJNo> <RqTime>2021/03/12 11:44:16.799</RqTime> <RsTime>2021/3/12 上午 11:44:17</RsTime> </RsHeader> <SvcRs> <Rs> <ErrMessage>succeed:OK</ErrMessage> <OrderNo>20210312114417544USDJPY</OrderNo> </Rs> </SvcRs> </GEPS>
B11: 006 | C11: 商品應用部 | D11: 金融市場科 | E11: TWTXN00065 | F11: 外幣留單撮合服務(Foreign Exchange Order Service) | G11: FOREX | H11: FUNDELETEFXORDER | I11: 刪除留單紀錄(DeleteFxOrder) | J11: 刪除留單紀錄(DeleteFxOrder) | K11: D | M11: 1 | N11: 44927 | O11: 金融市場科 | P11: 新網銀說未來不打算保留此功能 | Q11: http://10.11.35.51:8091/FxOrderWebservice.asmx/funFxOrderWS?xmlData= <?xml version="1.0" encoding="UTF-8"?> <GEPS> <RqHeader> <MsgID>FUNDELETEFXORDER</MsgID> <MsgType>G</MsgType> <ChlName>NETBANK</ChlName> <ChlEJNo>MMA-FUNDELETEFXORDER-0002107733389</ChlEJNo> <ChlSendTime>2021/03/12 11:46:06.801</ChlSendTime> <TxnID>V2700</TxnID> <BranchID>SPHNETBANK01</BranchID> <TermID>FXORDER@NETBANK</TermID> <UserID/> <SignID/> </RqHeader> <SvcRq> <Rq> <OrderNo>20210312114417544USDJPY</OrderNo> <CustId>A1211114150</CustId> </Rq> </SvcRq> </GEPS> | R11: <?xml version="1.0" encoding="utf-8"?> <GEPS> <RsHeader> <RsStat> <RsStatCode>SUCCESS</RsStatCode> <Desc>刪除留單成功</Desc> </RsStat> <Overrides><Override /> </Overrides> <ChlEJNo>MMA-FUNDELETEFXORDER-0002107733389</ChlEJNo> <EJNo>MMA-FUNDELETEFXORDER-0002107733389</EJNo> <RqTime>2021/03/12 11:46:06.801</RqTime> <RsTime>2021/3/12 上午 11:46:07</RsTime> </RsHeader> <SvcRs> <Rs> <ErrMessage>succeed:OK</ErrMessage> </Rs> </SvcRs> </GEPS>
B12: 007 | C12: 商品應用部 | D12: 信用支付科 | E12: TWWEB00023 | F12: 信用卡網站後台維護系統(Credit Card) | G12: EWEB | H12: MemberRegisterCheckCardInfo | I12: MemberRegisterCardCheck | J12: MMA會員註冊檢核 | K12: Y | M12: 1 | N12: 45001 | O12: Callee | P12: 程式無異動，故不需另行開發 | Q12: {"Content":{"ID":"A151041672","Birthday":"19010101"},"Header":{"ApplicationName":"MMA","UserID":"A151041672"}} | R12: {"Result":{"Success":true,"Mobile":"0928XXX612","Email":"","IsPaperStatement":true},"Header":{"SessionID":"ks34t01tjjmmlejjbyqnrf2j","ApplicationName":"MMA","ReferenceNo":"ad6a85fb-d903-46fe-b01d-d1b4c3c9b172","UserID":"A151041672","RequestTime":"2022-08-26T11:17:20.5599317+08:00","TxCode":"","RemoteAddr":"10.11.36.146","PageName":"","IsWriteLog":true,"SsaToken":"","ClientRefNo":null,"ClientTimestamp":null},"ResultCode":"00","ResultMessage":"","Error":null}
B13: 008 | C13: 商品應用部 | D13: 信用支付科 | E13: TWWEB00023 | F13: 信用卡網站後台維護系統(Credit Card) | G13: EWEB | H13: LatestTx | I13: LatestTx | J13: 最新消費資料 | K13: Y | M13: 1 | N13: 45001 | O13: Callee | P13: 程式無異動，故不需另行開發 | Q13: {"Content":{"ID":"A131XXXX82"},"Header":{"ApplicationName":"EWEB2","UserID":"A131XXXX82"}} | R13: { "Result": { "IsCompanyUser": false, "Items": [ { "CardFlag": "1", "CardNo": "4XX1", "IsMobileCard": false, "AuthDate": "2021/12/27", "AuthTime": "14:06:11", "Memo": "永豐ＴａＰａｙ驗證ＥＰＯＳ商店 ", "AuthAmt": 4001.0, "AuthAmtDesc": "4,001 ", "CountryCode": "TW", "AuthResult": "成功" }, { "CardFlag": "1", "CardNo": "4XX1", "IsMobileCard": false, "AuthDate": "2021/12/23", "AuthTime": "18:23:36", "Memo": "永豐ＴａＰａｙ驗證ＥＰＯＳ商店 ", "AuthAmt": 4001.0, "AuthAmtDesc": "4,001 ", "CountryCode": "TW", "AuthResult": "成功" } ] }, "Header": { "SessionID": "", "ApplicationName": "EWEB2", "ReferenceNo": "7fa756e2-d3e0-4691-854b-7ba4c9320c76", "UserID": "A131022582", "RequestTime": "2022-09-01T09:45:13.8539161+08:00", "TxCode": "", "RemoteAddr": "10.11.33.39", "PageName": "", "IsWriteLog": true, "SsaToken": "", "ClientRefNo": "7fa756e2-d3e0-4691-854b-7ba4c9320c76", "ClientTimestamp": "2022-09-01T09:45:13.8539161+08:00" }, "ResultCode": "00", "ResultMessage": "", "Error": null }
B14: 009 | C14: 商品應用部 | D14: 信用支付科 | E14: TWWEB00023 | F14: 信用卡網站後台維護系統(Credit Card) | G14: EWEB | H14: OutstandingDetail | I14: OutstandingDetail | J14: 消費明細查詢 (未結帳) | K14: Y | M14: 1 | N14: 45001 | O14: Callee | P14: 程式無異動，故不需另行開發 | Q14: {"Content":{"ID":"A131XXXX82","DateYYYYMMDD":"","IsExcludePaidUp":true},"Header":{"ApplicationName":"EWEB2","UserID":"A131XXXX82"}} | R14: { "Result": { "IsExcludePaidUp": true, "Detail": [ { "CurrencyCode": "000", "CurrencyName": "臺幣", "PID": "A131XXXX82 ", "CARD_TYPE": "3", "CardLast4": "4XX3", "TXDATE": "2020/04/17", "DEDATE": "2020/04/19", "TXCODE": "", "MEMO": "A- 屈臣氏Ｓ０２３３伊通店 ", "TXCUR": " ", "TXAMT": "", "AMT": "333", "PROD": "420", "EMBOSSING_TYPE": "001", "CardNoLast4": "4XX3", "CARDNAME": "升等商務御璽卡" } ], "SubTotal": [ { "CurrencyCode": "000", "CurrencyName": "臺幣", "Count": 19, "SubTotalAmt": "18,790" } ], "IsCompanyUser": false }, "Header": { "SessionID": "", "ApplicationName": "EWEB2", "ReferenceNo": "e82cd68a-bf8a-4699-97b5-acbfe267853c", "UserID": "A131022582", "RequestTime": "2022-09-01T09:51:05.9653362+08:00", "TxCode": "", "RemoteAddr": "10.11.140.10", "PageName": "", "IsWriteLog": true, "SsaToken": "", "ClientRefNo": null, "ClientTimestamp": null }, "ResultCode": "00", "ResultMessage": "", "Error": null }
B15: 010 | C15: 商品應用部 | D15: 信用支付科 | E15: TWWEB00023 | F15: 信用卡網站後台維護系統(Credit Card) | G15: EWEB | H15: RecentBill | I15: RecentBill | J15: 近期帳單查詢 | K15: Y | M15: 1 | N15: 45001 | O15: Callee | P15: 程式無異動，故不需另行開發 | Q15: {"Content":{"ID":"M151XXXX91","BillDateYYYYMM":"201704"},"Header":{"ApplicationName":"EWEB2","UserID":"A131XXXX82"}} | R15: { "Result": { "IsCompanyUser": false, "BillType": 0, "BaseData": { "ID": "M151147491", "CustName": "", "BillDate": "201706", "STMTDATE": "2017/06/06", "DUEDATE": "2017/06/21", "IsLineCR": false, "IntRate": "7.50%", "IntDate": "2017/09" }, "BillAmounts": [ { "CurrencyCode": "000", "CurrencyName": "臺幣", "PREVBAL": "120,659", "PREVPAYAMT": "0", "NEWADDAMT": "229,839", "FINCHARGE": "2,499", "LATECHARGE": "0", "CURRBAL": "352,997", "DUEAMT": "290,487", "DDAMT": "352,997", "DDBANK": "永豐銀行", "DDAcountNo": "3333333xxxx888", "ACT_LINE_CR": "N", "LastPaymentDate": "2015/10/10", "IntRate": 7.5, "IntDate": "201709", "LastPaymentAmt": "20,141", "TotalPaymentAmt": "29,650", "PaymentRecords": [ { "TXDATE": "2021/04/29", "DEDATE": "2021/04/29", "MEMO": "永豐自扣已入帳，謝謝！", "AMT": "-552" }, { "TXDATE": "2021/05/03", "DEDATE": "2021/05/03", "MEMO": "你的付款已入帳，謝謝！", "AMT": "29,098" } ] } ], "BillDeductMsgs": [ "您的預定扣款金額 臺幣 352,997 元將於 2017/06/21 透過 永豐銀行 帳號「3333333xxxx888」自動扣款，請於預定扣款日前一營業日存足帳戶餘額。如須申請帳單分期請於自動扣款日前5日完成申請。" ], "Reward": { "AddPoint": "1568", "AdjustPoint": "0", "ExchangePoint": "0", "TotalPoint": "5264", "ExpiringPoint": "0" }, "BillRecords": [ { "CurrencyCode": "000", "CurrencyName": "臺幣", "TXDATE": "2017/04/02", "DEDATE": "2017/06/01", "CardNo": "1806", "MEMO": " 6-XXXXX ", "AMT": "21", "TXAMT": "", "TXCUR": "", "CURDATE": "", "INST_RATE": "", "INST_AMT": "", "COUNTRY": " ", "TXCode": "3 " } ], "CashAdvanceInfo": { "CreditCardLimit": "2000000", "CreditAvailable": "0", "CashLimit": "0", "CashAvailable": "0", "AuthAmount": "0" }, "AsymmetricInstallmentInfo": [ { "TXDATE": "2021/03/05", "MEMO": "神腦蘋果手機60000(1624)", "AMT": "60,000", "INSAMT_MEMO": "第1-12期6成金額36,000、第13-24期4成金額24,000", "PAYAMT_MEMO": "第1-12期3,000、第13-24期2,000" } ] }, "Header": { "SessionID": "96c47e89-f50c-4406-b9bf-0eae6a308895", "ApplicationName": "EWEB2", "ReferenceNo": "ffc036ee-5f86-4826-b1e1-05ce7ffcc0e2", "UserID": "", "RequestTime": "2017-11-08T15:58:52.262743+08:00", "TxCode": "", "RemoteAddr": "10.11.33.40", "PageName": "", "IsWriteLog": true, "SsaToken": "", "ClientRefNo": "ffc036ee-5f86-4826-b1e1-05ce7ffcc0e2", "ClientTimestamp": "2017-11-08T15:58:52.262743+08:00" }, "ResultCode": "00", "ResultMessage": "", "Error": null }
B16: 011 | C16: 商品應用部 | D16: 信用支付科 | E16: TWBOS00017 | F16: 信用卡網站後台維護系統(Credit Card) | G16: EWEB | H16: OtpState | I16: OtpState | J16: OtpSvc - 查詢客戶DisplayCard狀態 | K16: Y | M16: 1 | N16: 45001 | O16: Callee | P16: 程式無異動，故不需另行開發 | Q16: Identity=A123123123 | R16: <OtpResponse xmlns:xsi="http://www.w3.org/2001/XMLSchema-instance" xmlns:xsd="http://www.w3.org/2001/XMLSchema" xmlns="http://tempuri.org/"> <Result>true</Result> <UserId>A123123123</UserId> <UserName>teete</UserName> <Code>0040</Code> <Message>登入MMA成功-DisplayCard OTP</Message> <TranSerial>49334</TranSerial> <CardNo>5243073229557395</CardNo> <OtpState>1</OtpState> <Issues>4</Issues> <ErrorCount>0</ErrorCount> </OtpResponse>
B17: 012 | C17: 商品應用部 | D17: 信用支付科 | E17: TWBOS00017 | F17: 信用卡網站後台維護系統(Credit Card) | G17: EWEB | H17: cardGetMain | I17: cardGetMain | J17: 查詢大戶信用卡資訊 | K17: Y | M17: 1 | N17: 45001 | O17: Callee | P17: 程式無異動，故不需另行開發 | Q17: CARD=552054XXXX133709; | R17: <CardGetMain><QueryResult>SUCCESS</QueryResult><PID></PID><CARD>552054XXXX133709</CARD><ErrLog></ErrLog><QueryData><CurrBal>29194</CurrBal><DueAmt>2940</DueAmt><DueDate>20220729</DueDate><StmtDate>20220703</StmtDate><LastPayTxdate>20080521</LastPayTxdate><LastPayAmt>3966</LastPayAmt><CreditLimit>000150000</CreditLimit><CreditAvailable>+000474738</CreditAvailable><Bonus>0</Bonus><IntRate>750</IntRate><EmpFlag>N</EmpFlag><VIPFlag>N</VIPFlag><WZFlag>N</WZFlag><EBILL>N</EBILL><DDAcct></DDAcct></QueryData></CardGetMain>
B18: 013 | C18: 商品應用部 | D18: 信用支付科 | E18: TWBOS00017 | F18: 信用卡網站後台維護系統(Credit Card) | G18: EWEB | H18: getDAWHORet | I18: getDAWHORet | J18: 大戶卡歷史回饋查詢 | K18: Y | M18: 1 | N18: 45001 | O18: Callee | P18: 程式無異動，故不需另行開發 | Q18: PID=A131418006;STMTMM=202207; | R18: <GetDAWHORet><STMTMM>202207</STMTMM><PID>A131418006</PID><QueryResult>SUCCESS</QueryResult><ErrLog></ErrLog><Returning>0</Returning></GetDAWHORet>
B19: 014 | C19: 商品應用部 | D19: 信用支付科 | E19: TWBOS00017 | F19: 信用卡網站後台維護系統(Credit Card) | G19: EWEB | H19: getDAWHOCardStatus | I19: getDAWHOCardStatus | J19: 大戶卡狀態查詢 | K19: Y | M19: 1 | N19: 45001 | O19: Callee | P19: 程式無異動，故不需另行開發 | Q19: PID=A111XXX967; | R19: <DAWHOCardStatus><PID>A111XXX967</PID><QueryResult>SUCCESS</QueryResult><ErrLog></ErrLog><DetailData><Detail TypeFace="212392" Status="4" /></DetailData></DAWHOCardStatus>
B20: 015 | C20: 商品應用部 | D20: 信用支付科 | E20: TWBOS00017 | F20: 信用卡網站後台維護系統(Credit Card) | G20: EWEB | H20: getDDFlag | I20: getDDFlag | J20: 大戶卡台幣帳戶自扣註記 | K20: Y | M20: 1 | N20: 45001 | O20: Callee | P20: 程式無異動，故不需另行開發 | Q20: PID=A111XXX967; | R20: <GetDDFlag><PID>A111316967</PID><QueryResult>SUCCESS</QueryResult><ErrLog></ErrLog><DDFlag>Y</DDFlag></GetDDFlag>
B21: 016 | C21: 商品應用部 | D21: 信用支付科 | E21: TWBOS00017 | F21: 信用卡網站後台維護系統(Credit Card) | G21: EWEB | H21: getBLHSHWithPaysum | I21: getBLHSHWithPaysum | J21: 大戶卡累積已繳金額查詢 | K21: Y | M21: 1 | N21: 45001 | O21: Callee | P21: 程式無異動，故不需另行開發 | Q21: PID=A131418006; | R21: <GetBLHSHWithPaysum><PID>A131418006 </PID><QueryResult>SUCCESS</QueryResult><ErrLog></ErrLog><STMTMM>202207</STMTMM><CURRBAL>29194.00</CURRBAL><DUEAMT>2940.00</DUEAMT><DUEDATE>20220729</DUEDATE><LPAYSUM>11541.00</LPAYSUM></GetBLHSHWithPaysum>
